<?xml version="1.0" ?>

<robot name="fanuc_m16ib20">
  <!-- --------------------------------------------------------------------------- -->
  <link name="world"/>
  <link name="base"/>
  <link name="base_link">
    <inertial>
        <origin
          xyz="0.0168771383054672 0.169315739028866 0.0412800634081652"
          rpy="0 0 0" />
        <mass
          value="15.2527879055871" />
        <inertia
          ixx="0.240635267432976"
          ixy="0.0100242488168428"
          ixz="-0.0305033975601131"
          iyy="0.271707940140716"
          iyz="-0.00725830289125767"
          izz="0.210184758127924" />
      </inertial>
    <visual>
      <origin rpy="0 0 0" xyz="0 0 0"/>
      <geometry>
        <mesh filename="visual/base_link.stl"/>
      </geometry>
      <material name="robot_yellow">
        <color rgba="1 0.5 0 1.0"/>
      </material>
    </visual>
    <collision>
      <origin rpy="0 0 0" xyz="0 0 0"/>
      <geometry>
        <mesh filename="collision/base_link.stl"/>
      </geometry>
    </collision>
  </link>
  <link name="link_1">
    <inertial>
      <origin rpy="0 0 0" xyz="0.0726897307131149 0.01726181100338 0.146189542933749"/>
      <mass value="8.58482432876493"/>
      <inertia ixx="0.0773051230689542" ixy="-0.00723379157253982" ixz="-0.000989343165238307" iyy="0.0723962945181877" iyz="-0.00461031639489372" izz="0.0825875841593164"/>
    </inertial>
    <visual>
      <origin rpy="0 0 0" xyz="0 0 0"/>
      <geometry>
        <mesh filename="visual/link_1.stl"/>
      </geometry>
      <material name="robot_yellow">
        <color rgba="1 0.5 0 1.0"/>
      </material>
    </visual>
    <collision>
      <origin rpy="0 0 0" xyz="0 0 0"/>
      <geometry>
        <mesh filename="collision/link_1.stl"/>
      </geometry>
    </collision>
  </link>
  <link name="link_2">
    <inertial>
      <origin rpy="0 0 0" xyz="-0.0302703665097071 -0.0903873349659628 0.28992958820209"/>
      <mass value="8.2150449017131"/>
      <inertia ixx="0.453073068816237" ixy="-0.00379770698429958" ixz="0.0071807966172984" iyy="0.457047499741872" iyz="-0.00913275289112151" izz="0.0235672287466738"/>
    </inertial>
    <visual>
      <origin rpy="0 0 0" xyz="0 0 0"/>
      <geometry>
        <mesh filename="visual/link_2.stl"/>
      </geometry>
      <material name="robot_yellow">
        <color rgba="1 0.5 0 1.0"/>
      </material>
    </visual>
    <collision>
      <origin rpy="0 0 0" xyz="0 0 0"/>
      <geometry>
        <mesh filename="collision/link_2.stl"/>
      </geometry>
    </collision>
  </link>
  <link name="link_3">
    <inertial>
      <origin rpy="0 0 0" xyz="0.12723749942066 0.100227995458356 0.109934685293926"/>
      <mass value="9.67618904299885"/>
      <inertia ixx="0.136062842569301" ixy="-0.00510277484528786" ixz="-0.0547361392761174" iyy="0.154610667545871" iyz="0.00260387431850614" izz="0.118176278176851"/>
    </inertial>
    <visual>
      <origin rpy="0 0 0" xyz="0 0 0"/>
      <geometry>
        <mesh filename="visual/link_3.stl"/>
      </geometry>
      <material name="robot_yellow">
        <color rgba="1 0.5 0 1.0"/>
      </material>
    </visual>
    <collision>
      <origin rpy="0 0 0" xyz="0 0 0"/>
      <geometry>
        <mesh filename="collision/link_3.stl"/>
      </geometry>
    </collision>
  </link>
  <link name="pneumatics">
    <inertial>
      <origin rpy="0 0 0" xyz="0.00110933006746268 -0.0182404642175578 0.0204308326542739"/>
      <mass value="0.303487141008849"/>
      <inertia ixx="0.000727934906520687" ixy="4.58702687909596E-07" ixz="-1.0856626128454E-05" iyy="0.00115096933775526" iyz="0.000166632900798468" izz="0.000754234128728351"/>
    </inertial>
    <visual>
      <origin rpy="0 0 0" xyz="0 0 0"/>
      <geometry>
        <mesh filename="visual/pneumatics.stl"/>
      </geometry>
      <material name="">
        <color rgba="0.10196 0.10196 0.10196 1"/>
      </material>
    </visual>
    <collision>
      <origin rpy="0 0 0" xyz="0 0 0"/>
      <geometry>
        <mesh filename="collision/pneumatics.stl"/>
      </geometry>
    </collision>
  </link>
  <link name="link_4">
    <inertial>
      <origin rpy="0 0 0" xyz="0.188625513593263 -0.0559577978885521 -0.00114940913552486"/>
      <mass value="4.60474836910352"/>
      <inertia ixx="0.0125033244602369" ixy="0.0101346194425775" ixz="-0.000488864344204214" iyy="0.0796306838019067" iyz="-3.96339927860412E-05" izz="0.0823799764969524"/>
    </inertial>
    <visual>
      <origin rpy="0 0 0" xyz="0 0 0"/>
      <geometry>
        <mesh filename="visual/link_4.stl"/>
      </geometry>
      <material name="robot_yellow">
        <color rgba="1 0.5 0 1.0"/>
      </material>
    </visual>
    <collision>
      <origin rpy="0 0 0" xyz="0 0 0"/>
      <geometry>
        <mesh filename="collision/link_4.stl"/>
      </geometry>
    </collision>
  </link>
  <link name="link_5">
    <inertial>
      <origin rpy="0 0 0" xyz="0.024900358966052 -0.0224006698492462 7.37344001411344E-08"/>
      <mass value="0.367816174627401"/>
      <inertia ixx="0.000671984183699895" ixy="-0.000199206306194321" ixz="1.12002081623748E-09" iyy="0.000692587871424379" iyz="3.53309816391218E-10" izz="0.000710717591297149"/>
    </inertial>
    <visual>
      <origin rpy="0 0 0" xyz="0 0 0"/>
      <geometry>
        <mesh filename="visual/link_5.stl"/>
      </geometry>
      <material name="robot_yellow">
        <color rgba="1 0.5 0 1.0"/>
      </material>
    </visual>
    <collision>
      <origin rpy="0 0 0" xyz="0 0 0"/>
      <geometry>
        <mesh filename="collision/link_5.stl"/>
      </geometry>
    </collision>
  </link>
  <link name="link_6">
    <inertial>
      <origin rpy="0 0 0" xyz="0.0302639071241406 -3.46944695195361E-17 -2.22044604925031E-16"/>
      <mass value="0.0344052830581641"/>
      <inertia ixx="3.4435938758267E-05" ixy="-2.54557813387769E-20" ixz="4.98349196091915E-21" iyy="2.11531436012608E-05" iyz="4.55280209149186E-21" izz="2.1317868300063E-05"/>
    </inertial>
    <visual>
      <origin rpy="0 0 0" xyz="0 0 0"/>
      <geometry>
        <mesh filename="visual/link_6.stl"/>
      </geometry>
      <material name="robot_yellow">
        <color rgba="1 0.5 0 1.0"/>
      </material>
    </visual>
    <collision>
      <origin rpy="0 0 0" xyz="0 0 0"/>
      <geometry>
        <mesh filename="collision/link_6.stl"/>
      </geometry>
    </collision>
  </link>
  <link name="flange"/>

  <!-- --------------------------------------------------------------------------- -->

  <link name="force_sensor">
    <visual>
      <origin rpy="0 0 0" xyz="0 0 0"/>
      <geometry>
        <mesh filename="visual/fs_leptrino.stl"/>
      </geometry>
      <material name="fs_blue">
        <color rgba="0 0 1 1.0"/>
      </material>
    </visual>
    <collision>
      <origin rpy="0 0 0" xyz="0 0 0"/>
      <geometry>
        <mesh filename="collision/fs_leptrino.stl"/>
      </geometry>
    </collision>
  </link>

  <!-- --------------------------------------------------------------------------- -->

  <link name="tool"/>

  <!-- --------------------------------------------------------------------------- -->

  <link name="rod_mount">
      <visual>
        <origin xyz="0 0 0" rpy="0 0 0"/>
        <geometry>
          <mesh filename="visual/rod_mount.stl"/>
        </geometry>
        <material name="tool_green_1">
          <color rgba="0 0.8 0 1.0" />
        </material>
      </visual>
      <collision>
        <origin xyz="0 0 0" rpy="0 0 0"/>
        <geometry>
          <mesh filename="collision/rod_mount.stl"/>
        </geometry>
      </collision>
    </link>
    <link name="rod">
      <visual>
        <origin xyz="0 0 0" rpy="0 0 0"/>
        <geometry>
          <mesh filename="visual/rod_l150.stl"/>
        </geometry>
        <material name="tool_green_2">
          <color rgba="0.1 0.8 0 1.0" />
        </material>
      </visual>
      <collision>
        <origin xyz="0 0 0" rpy="0 0 0"/>
        <geometry>
          <mesh filename="collision/rod_l150.stl"/>
        </geometry>
      </collision>
    </link>
    <link name="pad_mount">
      <visual>
        <origin xyz="0 0 0" rpy="0 0 0"/>
        <geometry>
          <mesh filename="visual/4pads_mount_150mm.stl"/>
        </geometry>
        <material name="tool_green_3">
          <color rgba="1 0 0 1.0" />
        </material>
      </visual>
      <collision>
        <origin xyz="0 0 0" rpy="0 0 0"/>
        <geometry>
          <mesh filename="collision/4pads_mount_150mm.stl"/>
        </geometry>
      </collision>
    </link>

  <!-- --------------------------------------------------------------------------- -->

  <link name="tcp"/>

  <!-- --------------------------------------------------------------------------- -->

  <joint name="world-base_link" type="fixed">
    <origin rpy="0 0 0" xyz="0.000 0.000 -0.450"/>
    <parent link="world"/>
    <child link="base_link"/>
  </joint>
  <joint name="base_link-base" type="fixed">
    <origin rpy="0 0 0" xyz="0.000 0.000 0.450"/>
    <parent link="base_link"/>
    <child link="base"/>
  </joint>
  <joint name="joint_1" type="revolute">
    <origin rpy="0 0 0" xyz="0 0 0.2865"/>
    <parent link="base_link"/>
    <child link="link_1"/>
    <axis xyz="0 0 1"/>
    <limit effort="0" lower="-2.0943951023931953" upper="2.0943951023931953" velocity="4.54"/>
  </joint>
  <joint name="joint_2" type="revolute">
    <origin rpy="0 0 0" xyz="0.075 -0.065 0.1635"/>
    <parent link="link_1"/>
    <child link="link_2"/>
    <axis xyz="0 1 0"/>
    <limit effort="0" lower="-1.2566370614359172" upper="2.0943951023931953" velocity="4.19"/>
  </joint>
  <joint name="joint_3" type="revolute">
    <origin rpy="0 0 0" xyz="0 0 0.64"/>
    <parent link="link_2"/>
    <child link="link_3"/>
    <axis xyz="0 -1 0"/>
    <limit effort="0" lower="-1.5707963267948966" upper="1.5707963267948966" velocity="4.54"/>
  </joint>
  <joint name="joint_3-pneumatics" type="fixed">
    <origin rpy="-1.5708 0 -1.5708" xyz="0.0155 0.0775 0.072"/>
    <parent link="link_3"/>
    <child link="pneumatics"/>
    <axis xyz="0 0 0"/>
  </joint>
  <joint name="joint_4" type="revolute">
    <origin rpy="0 0 0" xyz="0.2555 0.065 0.195"/>
    <parent link="link_3"/>
    <child link="link_4"/>
    <axis xyz="-1 0 0"/>
    <limit effort="0" lower="-2.0943951023931953" upper="2.0943951023931953" velocity="7.50"/>
  </joint>
  <joint name="joint_5" type="revolute">
    <origin rpy="0 0 0" xyz="0.4445 0 0"/>
    <parent link="link_4"/>
    <child link="link_5"/>
    <axis xyz="0 -1 0"/>
    <limit effort="0" lower="-1.8849555921538759" upper="1.8849555921538759" velocity="7.85"/>
  </joint>
  <joint name="joint_6" type="revolute">
    <origin rpy="0 0 0" xyz="0.03 0 0"/>
    <parent link="link_5"/>
    <child link="link_6"/>
    <axis xyz="-1 0 0"/>
    <limit effort="0" lower="-1.0471975511965976" upper="4.1887902047863905" velocity="12.57"/>
  </joint>
  <joint name="joint_6-flange" type="fixed">
    <origin rpy="0 0 0" xyz="0.045 0 0"/>
    <parent link="link_6"/>
    <child link="flange"/>
  </joint>

  <!-- --------------------------------------------------------------------------- -->

    <joint name="flange-tool" type="fixed">
      <origin xyz="0.0475 0 0" rpy="3.14 -1.5708 0" />
      <parent link="flange" />
      <child link="tool" />
    </joint>
    <joint name="force_sensor" type="fixed">
      <origin xyz="0 0 0" rpy="0 0 0" />
      <parent link="flange" />
      <child link="force_sensor" />
    </joint>
    
    

    <joint name="gripper1" type="fixed">
      <origin xyz="0 0 0" rpy="0 0 0" />
      <parent link="tool" />
      <child link="rod_mount" />
    </joint>
    <joint name="gripper2" type="fixed">
      <origin xyz="0 0 0" rpy="0 0 0" />
      <parent link="tool" />
      <child link="rod" />
    </joint>
    <joint name="gripper3" type="fixed">
      <origin xyz="0 0 0" rpy="0 0 0" />
      <parent link="tool" />
      <child link="pad_mount" />
    </joint>

     <joint name="tool-tcp" type="fixed">
      <origin xyz="0.150 0 0.250" rpy="0 0 0" />
      <parent link="tool" />
      <child link="tcp" />
    </joint>



</robot>
